Workbook

Sheet Tabla de contenidos
B2: Sección | C2: Hoja | D2: Descripción
B3: Definición del problema | C3: Objetivo | D3: Objetivo general del análisis
C4: Criterios | D4: Criterios principales del modelo AHP
B5: Construcción del FODA | C5: Subcriterios_Fortalezas | D5: Fortalezas consideradas como factores internos favorables para la integración económica
C6: Subcriterios_Debilidades | D6: Debilidades consideradas como factores internos que limitan la integración económica
C7: Subcriterios_Oportunidades | D7: Oportunidades consideradas como factores externos favorables para la integración económica
C8: Subcriterios_Amenazas | D8: Amenazas consideradas como factores externos que limitan la integración económica
B9: Escenarios | C9: Escenarios | D9: Definición de los escenarios
B10: Evaluación de preferencias | C10: EP_Criterios | D10: Determinación de los pesos relativos de los criterios principales mediante asignación directa y normalización jerárquica en el AHP
C11: EP_1 | D11: Determinación de las preferencias relativas de las Fortalezas mediante el método AHP
C12: EP_2 | D12: Determinación de las preferencias relativas de las Debilidades mediante el método AHP
C13: EP_3 | D13: Determinación de las preferencias relativas de las Oportunidades mediante el método AHP
C14: EP_4 | D14: Determinación de las preferencias relativas de las Amenazas mediante el método AHP
B15: Evaluación de desempeño | C15: ED_F | D15: Evaluación del desempeño de los escenarios respecto de las fortalezas identificadas
C16: ED_D | D16: Evaluación del desempeño de los escenarios respecto de las debilidades identificadas
C17: ED_O | D17: Evaluación del desempeño de los escenarios respecto de las oportunidades identificadas
C18: ED_A | D18: Evaluación del desempeño de los escenarios respecto de las amenazas identificadas
B19: Resultados | C19: EG_1 | D19: Evaluación global de los escenarios
C20: Analisis_Sensibilidad | D20: Comprobación de qué tan estable es una decisión cuando cambian los pesos o la importancia de los criterios.

Sheet Objetivo
B2: Objetivo General | C2: Evaluar el potencial estratégico de la integración económica de Paraguay en el MERCOSUR mediante un modelo multicriterio FODA-AHP sustentado en Economic Fitness y capacidades productivas, con datos correspondientes al año 2024.
B4: Título corto | C4: Potencial de integración productiva de Paraguay en el MERCOSUR
A14: << Volver a la Tabla de contenidos

Sheet Criterios
B2: # | C2: Criterios | D2: Descripción | E2: Indicadores | F2: Política de Decisión | G2: Tipo
B3: C1 | C3: Fortalezas | D3: Son factores internos favorables que permiten a cada escenario aprovechar oportunidades y enfrentar amenazas, generando ventajas competitivas. | E3: Factores Internos Positivos | F3: Maximizar | G3: Cualitativo / Cuantitativo
B4: C2 | C4: Debilidades | D4: Son factores internos desfavorables que limitan la capacidad de cada escenario para aprovechar oportunidades o aumentan su vulnerabilidad frente a las amenazas. | E4: Factores Internos Negativos | F4: Minimizar | G4: Cualitativo / Cuantitativo
B5: C3 | C5: Oportunidades | D5: Son factores externos, ajenos a cada escenario, que pueden resultar favorables para su desarrollo. | E5: Factores Externos Positivos | F5: Maximizar | G5: Cualitativo / Cuantitativo
B6: C4 | C6: Amenazas | D6: Son factores externos, fuera del control de cada escenario, que pueden afectar negativamente su desempeño. | E6: Factores Externos Negativos | F6: Minimizar | G6: Cualitativo / Cuantitativo
A9: << Volver a la Tabla de contenidos

Sheet Subcriterios_Fortalezas
B2: # | C2: Subcriterios | D2: Descripción | E2: Indicador | F2: Política de Decisión | G2: Tipo | H2: Justificación
B3: F1 | C3: Población Económicamente Activa | D3: La Población Económicamente Activa es el conjunto de personas de 15 años o más que están empleadas o que buscan activamente empleo. Refleja la capacidad laboral disponible de un país. | E3: Tasa de la Población Económicamente Activa (PEA) | F3: Mayor %PEA | G3: Cuantitativo | H3: Es un recurso interno del país. La PEA determina la oferta de mano de obra disponible para producir bienes y servicios. El crecimiento de la fuerza laboral a lo largo del tiempo expande la frontera de producción de un país y altera su ventaja competitiva (Salvatore, 2013). Una PEA grande y capacitada permite a un país integrarse mejor en cadenas productivas internacionales, atraer inversión extranjera y responder a la demanda global (Hastiadi, 2011; Pangestu & Ing, 2016).
B4: F2 | C4: Población Alfabetizada | D4: La Población Alfabetizada es el conjunto de personas de 15 años o más que pueden leer y escribir y comprender una declaración breve y sencilla sobre la vida cotidiana. | E4: Tasa de Población Alfabetizada (PA) | F4: Mayor %PA | G4: Cuantitativo | H4: Para que exista una economía compleja, es indispensable que sus miembros sepan leer, escribir y manipular símbolos (números y funciones matemáticas). Sin esta base de alfabetización, las sociedades no pueden avanzar hacia industrias de mayor valor agregado (Hausmann et al., 2014). La integración económica a menudo implica la transferencia de conocimientos desde países avanzados. Una población alfabetizada y educada permite a las naciones en desarrollo absorber estas tecnologías a un ritmo más rápido, acelerando el crecimiento a largo plazo (Salvatore, 2013).
B5: F3 | C5: Balance Energético | D5: El Balance Energético es la relación entre la producción, importación, exportación y consumo de energía de un país. Muestra si un país es autosuficiente o dependiente energéticamente. | E5: Índice de Excedente Energético | F5: Mayor Índice de Excedente Energético | G5: Cuantitativo | H5: El consumo de energía eléctrica se utiliza habitualmente como un indicador clave de la calidad de infraestructura de un país. El acceso a energía confiable y eficiente es parte de la infraestructura necesaria para atraer inversión extranjera y reducir los costos de producción dentro de un bloque integrado (Akbari et al., 2021).
B6: F4 | C6: Conectividad Marítima | D6: Mide la integración de un país en las redes globales de transporte marítimo de línea regular. Se refiere a la capacidad de un país para conectarse con el comercio internacional a través de puertos y rutas marítimas. | E6: Índice de Conectividad del Transporte Marítimo de Línea Regular (ICTML) | F6: Mayor ICTML | G6: Cuantitativo | H6: El acceso a los mercados depende en gran medida de la conectividad marítima, especialmente de los servicios de transporte marítimo regulares utilizados para importar y exportar productos manufacturados. La conectividad marítima potencia la ventaja comparativa de un país; por el contrario, una mala infraestructura desgasta los ingresos potenciales de los productores locales al encarecer la salida de sus productos al mercado regional (Hastiadi, 2011).
B7: F5 | C7: Red Vial General | D7: Es el conjunto de carreteras, autopistas y caminos que conectan ciudades y regiones dentro de un país. Facilita el transporte de personas y mercancías. La densidad de red pavimentada por superficie es un indicador que mide cuántos kilómetros de vías pavimentadas existen por unidad de superficie de un territorio. | E7: Densidad de Red Pavimentada por Superficie | F7: Mayor Densidad de Red Pavimentada | G7: Cuantitativo | H7: La provisión de infraestructura vial es un factor determinante en el crecimiento de la productividad a nivel sectorial. Además, influye directamente en la capacidad de una nación para especializarse en la producción de bienes específicos, facilitando su inserción en cadenas de suministro regionales (Hastiadi, 2011). La red vial permite que los trabajadores se desplacen a las plantas de producción y que los bienes lleguen a los puertos o aeropuertos para su exportación (Hausmann et al., 2014).
B8: F6 | C8: Logística Aérea | D8: Los servicios de transporte aéreo permiten la exportación de bienes y la conectividad global, facilitando el intercambio de conocimientos y productos complejos. La carga aérea hace referencia a la cantidad total de mercancías transportadas por vía aérea, medida en toneladas. Incluye exportaciones, importaciones y otras cargas comerciales movilizadas a través de los aeropuertos. | E8: Carga Aérea | F8: Mayor Carga Aérea | G8: Cuantitativo | H8: Al igual que otras formas de transporte, una infraestructura aérea eficiente reduce los costos directos de comercio y los tiempos de entrega (Hastiadi, 2011). El transporte aéreo es vital para el funcionamiento de las redes de producción regionales. Permite el flujo fluido de componentes de alto valor que requieren logística ágil para mantener la eficiencia de la cadena global de valor (Hausmann et al., 2014; Pangestu & Ing, 2016).
B9: F7 | C9: Innovación y Desarrollo Tecnológico | D9: El Índice Global de Innovación (IGI) mide la capacidad y el desempeño innovador de los países. Es publicado por la World Intellectual Property Organization (WIPO). La metodología se basa en 7 pilares principales: 1. Instituciones 2. Capital humano e investigación 3. Infraestructura 4. Sofisticación del mercado 5. Sofisticación empresarial 6. Resultados de conocimiento y tecnología 7. Resultados creativos | E9: Índice Global de Innovación (IGI) | F9: Mayor IGI | G9: Cuantitativo | H9: La innovación se basa en la acumulación de capacidades o conocimiento tácito, que es difícil de transferir o imitar y representa el motor real de la productividad y el crecimiento a largo plazo (Castañeda & Romero-Padilla, 2018; Çınar et al., 2022). El avance tecnológico ha acelerado exponencialmente la integración de las sociedades hacia un espacio económico unificado (González et al., 2023). La tecnología permite que servicios complejos (como la propiedad intelectual y la consultoría) se integren profundamente con sectores industriales, creando vías de diversificación que antes eran invisibles en análisis que solo consideraban bienes físicos (Zaccaria et al., 2018).
B10: F8 | C10: Economic Fitness | D10: Es una métrica no monetaria diseñada para medir la competitividad y poder productivo de los países. | E10: Fitness de países (Fc) | F10: Mayor Fitness | G10: Cuantitativo | H10: El Economic Fitness es un indicador que permite identificar si el crecimiento de un país o bloque económico proviene de capacidades industriales reales y diversificadas, en lugar de depender de factores temporales como el aumento de precios de materias primas. Además, al aplicarse a grupos de países como si fueran un “macro-país”, muestra cómo la integración genera un sistema productivo compartido y más complejo, reflejando capacidades económicas conjuntas y no solo la suma de las economías individuales (Tacchella et al., 2012).
B11: F9 | C11: Capacidades Productivas | D11: Son “fragmentos” de conocimiento que permiten a una sociedad realizar actividades necesarias para fabricar productos. | E11: Capacidades Productivas Acumuladas | F11: Mayor Capacidad Productiva Acumulada | G11: Cuantitativo | H11: Ningún país posee todas las capacidades necesarias para fabricar todos los productos; la integración a través de mercados permite que el conocimiento que poseen unos pocos llegue a muchos, haciendo a las naciones colectivamente más sabias (Hausmann et al., 2014).
A13: << Volver a la Tabla de contenidos

Sheet Subcriterios_Debilidades
B2: # | C2: Subcriterios | D2: Descripción | E2: Indicadores | F2: Política de Decisión | G2: Tipo | H2: Justificación
B3: D1 | C3: Inflación | D3: La inflación, medida por el índice de precios al consumidor, refleja el cambio porcentual anual en el costo para el consumidor promedio de adquirir una canasta de bienes y servicios que puede fijarse o cambiarse en intervalos específicos, como por ejemplo anualmente. | E3: Inflación, precios al consumidor (% anual) | F3: Menor Inflación | G3: Cuantitativo | H3: La inflación es un criterio de convergencia fundamental cuyo incumplimiento ha postergado repetidamente los procesos de integración monetaria y la adopción de monedas únicas. Tasas de inflación elevadas o divergentes entre socios comerciales generan asimetrías en la competitividad real, ya que, dentro de una unión económica, los países pierden la herramienta del tipo de cambio para compensar diferenciales en sus costos de vida y producción. Asimismo, una inflación alta y variable suele derivar de políticas macroeconómicas inestables que resultan en un crecimiento real modesto y aumentan la vulnerabilidad financiera al impedir que los Estados manejen su carga de deuda mediante ajustes monetarios, elevando así el riesgo de crisis de solvencia dentro del bloque (Salvatore, 2013).
B4: D2 | C4: Control de Corrupción | D4: El nivel de corrupción se refiere a la frecuencia con la que el poder público es utilizado de forma indebida para obtener beneficios privados, mediante sobornos, malversación de recursos o tráfico de influencias. El Control de la Corrupción mide las percepciones sobre el grado en que estas prácticas son prevenidas y controladas por las instituciones públicas, incluyendo la corrupción menor, la de gran escala y la captura del Estado por élites e intereses privados. La puntuación se expresa en una escala de 0 a 100, donde 100 representa el mejor desempeño en materia de gobernanza. | E4: Control de la Corrupción | F4: Mayor Control de Corrupción | G4: Cuantitativo | H4: La corrupción genera un impacto negativo como barrera institucional que limita significativamente el desarrollo y la profundidad de los mercados financieros. El ejercicio del poder público para beneficio privado distorsiona la estabilidad económica al deteriorar la calidad de los activos bancarios (incrementando la morosidad) y reducir la rentabilidad operativa. Asimismo, niveles elevados de corrupción actúan como un freno que restringe el acceso de la población a servicios financieros esenciales, lo que neutraliza los beneficios potenciales de la apertura económica y dificulta la implementación de las reformas estructurales necesarias para lograr una integración regional efectiva y sostenible (Toroyan & Anayiotos, 2009).
B5: D3 | C5: Vulnerabilidad Socioeconómica | D5: La vulnerabilidad socioeconómica se refiere a la condición de personas o grupos que, debido a limitaciones en sus ingresos, acceso a oportunidades o servicios básicos, tienen una mayor exposición a la pobreza, la desigualdad y la exclusión social. En este contexto, el índice de Gini mide el grado en que la distribución del ingreso (o del gasto de consumo) entre individuos u hogares se desvía de una distribución perfectamente equitativa. Un índice de Gini de 0 representa igualdad perfecta, mientras que un valor de 100 indica desigualdad perfecta. Por ello, valores más altos reflejan una mayor desigualdad y, en general, una mayor vulnerabilidad socioeconómica. | E5: Índice de Gini | F5: Menor Índice de Gini | G5: Cuantitativo | H5: La vulnerabilidad socioeconómica y la desigualdad de ingresos presentan obstáculos críticos para los procesos de integración económica, ya que elevan el riesgo de inversión, generan inestabilidad sociopolítica y erosionan la confianza mutua necesaria para sostener acuerdos a largo plazo (El Amri & El Jouali, 2026). Al concentrarse los beneficios de la apertura en las economías más avanzadas, los países con altos niveles de desigualdad enfrentan fuertes tensiones internas y presiones sociales que impulsan el retorno al proteccionismo o colapso del bloque regional (Salvatore, 2013; Sohn, 2013).
B6: D4 | C6: Dependencia de Productos Primarios | D6: La dependencia de productos primarios se refiere a la situación en la que la economía de un país depende principalmente de la producción y exportación de materias primas o recursos naturales, en lugar de productos industrializados o servicios. Los productos primarios son aquellos que se obtienen directamente de la naturaleza. | E6: Participación de productos primarios en las exportaciones totales (%) | F6: Menor participación de productos primarios en las exportaciones totales (%) | G6: Cuantitativo | H6: La integración regional se facilita cuando los países producen bienes que otros en la misma región necesitan. Sin embargo, en regiones como África Oriental, muchos países dependen de los mismos productos agrícolas o minerales, lo que los convierte en competidores por los mismos mercados externos (como Europa o Asia) en lugar de socios comerciales (Sohn, 2013). Así también, los productos primarios enfrentan una demanda y oferta altamente inelásticas, lo que genera fluctuaciones brutales en los precios internacionales (Salvatore, 2013).
B7: D5 | C7: Nivel de Estrés Hídrico | D7: El nivel de estrés hídrico, expresado como la extracción de agua dulce como proporción de los recursos hídricos disponibles, es la relación entre el total de agua dulce extraída por todos los sectores principales y el total de recursos hídricos renovables, una vez consideradas las necesidades hídricas ambientales. Los sectores principales, incluyen la agricultura, la silvicultura y la pesca, la industria manufacturera, la industria eléctrica y los servicios. Este indicador también se conoce como intensidad de extracción de agua. | E7: Nivel de Estrés Hídrico | F7: Menor Nivel de Estrés Hídrico | G7: Cuantitativo | H7: El estrés hídrico es un factor limitante del crecimiento económico que compromete la capacidad productiva de los sectores agrícola e industrial (Hausmann et al., 2014; Kaniaru, 2015). Los países bajo estrés hídrico enfrentan una mayor vulnerabilidad en su seguridad alimentaria, viéndose obligados a depender de la importación de “agua virtual” (alimentos producidos externamente) para compensar sus déficits locales de recursos (Delbourg & Dinar, 2020). Esta condición no solo genera presiones sobre la balanza de pagos y drena recursos financieros, sino que también actúa como un catalizador de tensiones geopolíticas en regiones con cuencas compartidas, dificultando la cooperación y la estabilidad política necesarias para una integración económica regional exitosa y sostenible (Kaniaru, 2015).
B8: D6 | C8: Población en Situación de Inseguridad Alimentaria | D8: Porcentaje de personas en la población que viven en hogares clasificados como con inseguridad alimentaria moderada o grave. Un hogar se clasifica como con inseguridad alimentaria moderada o grave cuando al menos un adulto en el hogar ha declarado haber estado expuesto, en algún momento del año, a dietas de baja calidad y se ha visto obligado a reducir la cantidad de alimentos que normalmente consume debido a la falta de dinero u otros recursos. | E8: Tasa de Prevalencia de Inseguridad Alimentaria Moderada o Grave en la Población | F8: Menor Tasa de Prevalencia de Inseguridad Alimentaria Moderada o Grave en la Población | G8: Cuantitativo | H8: A pesar de que muchas regiones cuentan con un vasto potencial agrícola y una población mayoritariamente dedicada a este sector, la elevada dependencia hacia las importaciones de alimentos básicos (como carne, lácteos y cereales) provenientes de mercados externos, refleja una falta de integración en las cadenas de valor alimentarias locales y una infraestructura comercial insuficiente para aprovechar la diversidad ecológica regional. Al impedir la autosuficiencia colectiva, la inseguridad alimentaria drena divisas, aumenta la vulnerabilidad ante choques de precios internacionales y obliga a que los esfuerzos de integración se centren en la subsistencia básica en lugar de en la transformación industrial (Salvatore, 2013).
B9: D7 | C9: Pobreza Energética Multidimensional | D9: Indicador multidimensional del desempeño energético que integra, con pesos iguales, el acceso a electricidad, el acceso a combustibles y tecnologías limpias para cocinar, la oferta total de energía primaria per cápita y el consumo final total de energía per cápita. Se utiliza WAEPI-W2 = 100 − CEPI-W2, de manera que un valor mayor representa menor pobreza energética. | E9: Weighted Average Energy Poverty Index, escenario W2 (WAEPI-W2) | F9: Mayor WAEPI-W2 = menor pobreza energética y mejor desempeño relativo. | G9: Cuantitativo | H9: La incorporación de la pobreza energética como subcriterio en el análisis de la integración económica internacional se fundamenta en que la energía constituye una condición transversal para el bienestar de la población, el funcionamiento de los sistemas productivos y la reducción de las asimetrías estructurales entre países. La existencia de una infraestructura energética relevante o de abundantes recursos naturales no garantiza, por sí sola, que la población pueda acceder y utilizar servicios energéticos modernos, suficientes, limpios y asequibles. Por consiguiente, las diferencias existentes en materia energética pueden transformarse en debilidades internas para algunos países y en restricciones para la convergencia económica y social dentro de un bloque regional. En el primer estudio realizado para Paraguay, Pereira, González y Ríos (2020) plantearon que la pobreza energética no debía evaluarse exclusivamente mediante el acceso a electricidad. Los autores adoptaron un enfoque multidimensional que considera tres dimensiones fundamentales: accesibilidad, disponibilidad y asequibilidad. Estas dimensiones se representaron mediante cuatro indicadores: acceso a electricidad, acceso a combustibles y tecnologías limpias para cocinar, oferta total de energía primaria per cápita y consumo final total de energía per cápita. La investigación demostró que Paraguay podía presentar niveles relevantes de pobreza energética a pesar de contar con una elevada disponibilidad y producción de electricidad hidroeléctrica. Este resultado evidencia que la capacidad de generación energética de un país no necesariamente se traduce en una satisfacción suficiente y equilibrada de las necesidades energéticas de su población. Posteriormente, Pereira, González y Ríos (2021) ampliaron la aplicación de la metodología a Argentina, Brasil, Paraguay y Uruguay. El estudio permitió desarrollar una medición estandarizada, comparable y replicable de la pobreza energética multidimensional en los cuatro países fundadores del MERCOSUR. Los autores destacaron que estos países mantienen relaciones energéticas estrechas y presentan condiciones territoriales, sociales y económicas que justifican su evaluación conjunta. Asimismo, señalaron que el MERCOSUR constituye una plataforma apropiada para analizar, discutir e implementar políticas regionales destinadas a reducir las brechas energéticas y promover el bienestar de las poblaciones más vulnerables. La metodología se estructura en dos etapas. En la primera se calcula el Weighted Average Energy Poverty Index —WAEPI—, que sintetiza el grado de cumplimiento de las necesidades energéticas mediante una suma ponderada de los indicadores normalizados. En la segunda, el WAEPI se transforma en el Composite Energy Poverty Index —CEPI—, utilizado para representar la brecha respecto de un benchmark. Los tres escenarios propuestos permiten analizar la sensibilidad de los resultados a diferentes ponderaciones. El escenario W1 considera únicamente la accesibilidad; el W3 prioriza el acceso, pero incorpora disponibilidad y asequibilidad; mientras que el escenario W2 asigna un peso de 25 % a cada uno de los cuatro indicadores. Para el presente estudio se considera metodológicamente más apropiado utilizar el WAEPI correspondiente al escenario W2. Esta selección se justifica porque el análisis de integración económica requiere una visión equilibrada de las condiciones energéticas y no solamente de la cobertura eléctrica. El W2 reconoce que la electricidad, la cocción limpia, la disponibilidad de energía primaria y el consumo final desempeñan funciones complementarias en la explicación de la pobreza energética. Además, evita establecer a priori que una dimensión sea más importante que las demás, lo que resulta adecuado cuando el indicador será integrado posteriormente en una estructura multicriterio cuyos pesos generales serán determinados mediante el Proceso Analítico Jerárquico. El tercer trabajo de González et al. (2021) fortaleció esta aproximación al reemplazar el país externo de referencia por un benchmark promedio regional. Esta modificación permite interpretar el desempeño de cada país en relación con las condiciones efectivamente observadas dentro de la región, reduciendo el riesgo de sobreestimar las brechas mediante la comparación con economías que presentan estructuras energéticas y socioeconómicas muy diferentes. La propuesta mantiene las dimensiones de accesibilidad, disponibilidad y asequibilidad, pero mejora la pertinencia territorial del índice para evaluar a Argentina, Brasil, Paraguay y Uruguay. En el análisis AHP conviene utilizar directamente el WAEPI-W2, debido a que presenta una escala positiva y una orientación clara: un valor más elevado representa un mayor cumplimiento de las necesidades energéticas y, por tanto, una menor pobreza energética. El CEPI, en cambio, puede asumir valores positivos, negativos o iguales a cero al expresar brechas respecto del promedio regional, lo que dificulta su incorporación en procedimientos de normalización por suma o razón. El uso del WAEPI conserva la información y el orden relativo del CEPI, pero facilita su procesamiento dentro de la matriz multicriterio. En síntesis, la pobreza energética constituye una debilidad relevante para la integración económica porque refleja asimetrías en las condiciones necesarias para el desarrollo humano y productivo. El WAEPI-W2 ofrece una medida multidimensional, comparable, reproducible y compatible con el AHP, mientras que el benchmark regional proporciona una referencia contextualizada para el MERCOSUR. Los escenarios W1 y W3 pueden conservarse como análisis de sensibilidad, pero el W2 debe utilizarse como escenario central debido a su tratamiento equilibrado de las dimensiones energéticas.
A11: << Volver a la Tabla de contenidos

Sheet Subcriterios_Oportunidades
B2: # | C2: Subcriterios | D2: Descripción | E2: Indicadores | F2: Política de Decisión | G2: Tipo | H2: Justificación
B3: O1 | C3: Inversión Extranjera Directa | D3: La Inversión Extranjera Directa (IED) representa los flujos de capital transfronterizos que realiza un inversionista para obtener el control o una influencia significativa en una empresa de otro país. Se consolida mediante la suma del capital social, la reinversión de utilidades y otros capitales, estableciéndose la relación de inversión directa cuando se posee al menos el 10% de las acciones ordinarias con derecho a voto. | E3: IED, entrada neta de capital (% del PIB) | F3: Mayor IED como porcentaje del PIB | G3: Cuantitativo | H3: La IED permite la “fragmentación del proceso productivo”. Las empresas invierten en diferentes países de una región para especializar cada planta en una tarea específica, convirtiendo a la región en una “gran fábrica” (Hastiadi, 2011; Pangestu & Ing, 2016). La IED es el principal vehículo para trasladar nuevas ideas, tecnologías y habilidades gerenciales entre naciones. Esto acelera el crecimiento de los socios menos desarrollados y profundiza la interdependencia al integrar sus sistemas productivos con los de las naciones avanzadas (Salvatore, 2013).
B4: O2 | C4: Apertura Comercial | D4: La apertura comercial a menudo se mide como exportaciones netas sobre el PIB. Se utiliza como una variable que representa el nivel de regionalismo, ya que la integración misma crea apertura en sectores específicos de la economía. | E4: Tasa de Apertura Comercial | F4: Mayor Tasa de Apertura Comercial | G4: Cuantitativo | H4: La apertura permite a los países explotar sus ventajas comparativas, promoviendo la especialización y permitiendo que las empresas accedan a mercados más grandes para aprovechar economías de escala (El Amri & El Jouali, 2026). Un mayor grado de apertura económica promueve la globalización y facilita el flujo de capitales y la Inversión Extranjera Directa (IED), lo cual es esencial para solidificar los bloques económicos (Akbari et al., 2021).
A6: << Volver a la Tabla de contenidos

Sheet Subcriterios_Amenazas
B2: # | C2: Subcriterios | D2: Descripción | E2: Indicadores | F2: Política de Decisión | G2: Tipo | H2: Justificación
B3: A1 | C3: Riesgo Climático | D3: Analiza los impactos de los fenómenos meteorológicos extremos mediante tres categorías de riesgo: hidrológico, meteorológico y climatológico. En este índice, una posición más baja (más cercana al 1) significa mayor impacto/riesgo climático. Una posición más alta implica menor impacto relativo. El índice considera los impactos absolutos y relativos, utilizando seis indicadores clave: pérdidas económicas, víctimas mortales y personas afectadas, tanto en términos absolutos como relativos. | E3: Índice de Riesgo Climático | F3: Mayor Índice de Riesgo Climático | G3: Cuantitativo | H3: El cambio climático impacta directamente en el PIB y los estándares de vida al exacerbar la pobreza y la desigualdad entre países. Además, fenómenos extremos como inundaciones, sequías y calores intensos pueden degradar la infraestructura física crítica (redes de transporte y energía) y desestabilizar la seguridad alimentaria mediante la ruptura de las redes de distribución en los mercados internacionales. Finalmente, estos riesgos incrementan la probabilidad de conflictos y movilidad humana involuntaria, socavando la paz y la cohesión social necesarias para una cooperación económica transfronteriza efectiva (Tebaldi et al., 2023).
B4: A2 | C4: Barreras Arancelarias | D4: El arancel promedio simple aplicado se define como el promedio aritmético de los derechos de aduana ad valorem (o sus equivalentes) que un país impone efectivamente a sus importaciones bajo el principio de la Nación Más Favorecida (NMF). A diferencia del promedio ponderado por el comercio, este indicador trata a todas las categorías de productos con la misma importancia, independientemente de su volumen o valor comercial real. | E4: Arancel Promedio Simple Aplicado (%) | F4: Menor Arancel Promedio Simple Aplicado | G4: Cuantitativo | H4: Las barreras arancelarias influyen en la integración porque definen el grado de apertura de una economía y el costo de acceso de los mercados; su eliminación es la condición necesaria para materializar las redes de producción regionales y las economías de escala que sustentan el crecimiento compartido (El Amri & El Jouali, 2026).
A6: << Volver a la Tabla de contenidos

Sheet Escenarios
B2: # | C2: Escenarios | D2: Justificar
B3: E1 | C3: Paraguay como economía individual | D3: El escenario E1 representa a Paraguay considerado como una economía individual y constituye la línea de base nacional del estudio. Permite evaluar de manera específica sus capacidades productivas reveladas, fortalezas, debilidades, oportunidades y amenazas a partir de sus propias condiciones económicas, sociales, institucionales, logísticas, energéticas y ambientales. Su incorporación permite identificar el desempeño que Paraguay puede alcanzar mediante sus recursos, conocimientos productivos y condiciones estructurales actuales, sin atribuirle las capacidades adicionales que podrían derivarse de la agregación regional. Asimismo, permite analizar su potencial de transformación productiva y su nivel de inserción en el contexto regional e internacional.
B4: E2 | C4: MERCOSUR como sistema productivo agregado | D4: El escenario E2 representa al MERCOSUR considerado como un sistema productivo agregado. Su construcción combina, mediante reglas de agregación explícitas, los indicadores y las capacidades productivas reveladas de los países incluidos en el perímetro del estudio. Este escenario permite estimar la escala, diversidad productiva, acumulación de conocimiento, conectividad, capacidad logística e inserción internacional que pueden alcanzarse al considerar conjuntamente a las economías participantes. La comparación con el escenario E1 permite evaluar si la integración regional amplía la frontera productiva y estratégica disponible para Paraguay. No obstante, el escenario representa un potencial regional y no implica que todas las capacidades del bloque sean automática o inmediatamente accesibles para el país, ya que su aprovechamiento efectivo depende de la coordinación institucional, la infraestructura regional, la articulación de cadenas de valor, la transferencia de tecnología y la distribución de los beneficios de la integración.
A7: << Volver a la Tabla de contenidos

Sheet F1
A1: Escenario | B1: % PEA | D1: Subcriterio | E1: Población Económicamente Activa | H1: País | I1: % PEA | J1: Población Total | K1: PEA
A2: Paraguay | B2: =I4 -> 0.7027 | D2: Indicador | E2: Tasa de Población Económicamente Activa (PEA) | H2: Argentina | I2: 0.61862 | J2: 45696159 | K2: =I2*J2 -> 28268558
A3: MERCOSUR | B3: =I6 -> 0.6328758 | D3: Política de decisión | E3: Mayor Tasa de Población Económicamente Activa | H3: Brasil | I3: 0.63339 | J3: 2.1199857e+08 | K3: =I3*J3 -> 1.3427778e+08
D4: Estimación MERCOSUR | E4: El %PEA del MERCOSUR fue estimada mediante la agregación de los datos de Argentina, Brasil, Paraguay y Uruguay. Se calculó la PEA de cada país multiplicando la tasa de participación laboral por la población total, y luego se dividió la suma de las PEA nacionales entre la población total agregada del bloque. | H4: Paraguay | I4: 0.7027 | J4: 6929153 | K4: =I4*J4 -> 4869115.8
H5: Uruguay | I5: 0.65018 | J5: 3386587.5 | K5: =I5*J5 -> 2201891.5
H6: MERCOSUR | I6: =K6/J6 -> 0.6328758 | J6: =SUM(J2:J5) -> 268010473 | K6: =SUM(K2:K5) -> 1.6961734e+08
D7: Tasa de población activa, total (% de la población total mayor de 15 años) (estimación modelado OIT)
D8: Descripción | E8: La tasa de población activa es la proporción de la población de 15 años de edad o más económicamente activa: todas las personas que aportan trabajo para la producción de bienes y servicios durante un período específico.
D11: Fuente | E11: https://datos.bancomundial.org/indicador/SL.TLF.CACT.ZS
D12: Fecha de descarga | E12: 46163
D13: Población Total
D14: Fuente | E14: https://population.un.org/wpp/
D15: Fecha de descarga | E15: 46177
A22: << Volver a la Tabla de contenidos

Sheet F2
A1: Escenario | B1: % PA | D1: Subcriterio | E1: Población Alfabetizada | H1: País | I1: Tasa de alfabetización | J1: Población Total | K1: Población Alfabetizada
A2: Paraguay | B2: =I4 -> 0.94860001 | D2: Indicador | E2: Tasa de Población Alfabetizada (PA) | H2: Argentina | I2: 0.99139999 | J2: 45696159 | K2: =I2*J2 -> 45303172
A3: MERCOSUR | B3: =I6 -> 0.95545999 | D3: Política de decisión | E3: Mayor Tasa de Población Alfabetizada | H3: Brasil | I3: 0.94739998 | J3: 2.1199857e+08 | K3: =I3*J3 -> 2.0084744e+08
D4: Estimación MERCOSUR | E4: La tasa de alfabetización del MERCOSUR fue estimada mediante la agregación de los datos de Argentina, Brasil, Paraguay y Uruguay. Se calculó la PA de cada país multiplicando la tasa de alfabetización por la población total, y luego se dividió la suma de las PA nacionales entre la población total agregada del bloque. | H4: Paraguay | I4: 0.94860001 | J4: 6929153 | K4: =I4*J4 -> 6572994.6
H5: Uruguay | I5: 0.98910004 | J5: 3386587.5 | K5: =I5*J5 -> 3349673.8
H6: MERCOSUR | I6: =K6/J6 -> 0.95545999 | J6: =SUM(J2:J5) -> 268010473 | K6: =SUM(K2:K5) -> 2.5607328e+08
D8: Tasa de alfabetización, total de adultos (% de personas de 15 años y más)
D9: Descripción | E9: La tasa de alfabetización de adultos es el porcentaje de personas de 15 años o más que pueden leer y escribir y comprender una declaración breve y sencilla sobre su vida cotidiana.
D10: Fuente | E10: https://datos.bancomundial.org/indicador/SE.ADT.LITR.ZS
D11: Fecha de descarga | E11: 46163
D12: Población Total
D13: Fuente | E13: https://population.un.org/wpp/
D14: Fecha de descarga | E14: 46177
A20: << Volver a la Tabla de contenidos

Sheet F3
A1: Escenario | B1: Índice de excedente energético | D1: Subcriterio | E1: Balance Energético | H1: País | I1: 2024
A2: Paraguay | B2: =I4 -> 0.11833158 | D2: Indicador | E2: Índice de excedente energético | H2: Argentina | I2: =F3_ARG!B7 -> 0.34186433
A3: MERCOSUR | B3: =I6 -> 0.16970558 | D3: Descripción | E3: Mide la proporción de la oferta energética total que no es absorbida por el consumo interno final. | H3: Brasil | I3: =F3_BRA!B4 -> 0.10477227
H4: Paraguay | I4: =F3_PRY!B4 -> 0.11833158
D5: Fórmula | E5: 1 - (Consumo Final Total/Oferta Interna Total) | H5: Uruguay | I5: =F3_URY!B4 -> 0.11385414
D6: Política de decisión | E6: Mayor Índice de excedente energético | H6: MERCOSUR | I6: =AVERAGE(I2:I5) -> 0.16970558
D7: Estimación MERCOSUR | E7: Se calculó el promedio de los índices correspondientes a Argentina, Brasil, Paraguay y Uruguay.
D8: Nota metodológica | E8: Debido a la ausencia de una fuente internacional única que concentre los datos requeridos, se recurrió a las instituciones oficiales correspondientes de cada país. Los cálculos individuales y las fuentes utilizadas se presentan en las siguientes hojas (F3_ARG, F3_BRA, F3_PRY, F3_URY).
A19: << Volver a la Tabla de contenidos

Sheet F3_ARG
A1: Oferta Interna - Energía Primaria (ktep) | B1: 82931.31 | D1: Subcriterio | E1: Balance Energético
A2: Oferta Interna Total | B2: =B1 -> 82931.31 | D2: Indicador | E2: Índice de excedente energético
A3: Consumo Final - Energía primaria (ktep) | B3: 1019.0838 | D3: Fórmula | E3: 1 - (Consumo Final Total/Oferta Interna Total)
A4: Consumo Final - Energía Secundaria (ktep) | B4: 53560.97 | D4: País | E4: Argentina
A5: Consumo Final Total | B5: =B3+B4 -> 54580.054 | D5: Fuente | E5: https://www.argentina.gob.ar/econom%C3%ADa/energ%C3%ADa/planeamiento-energetico/balances-energeticos
A7: Tasa de excedente energético | B7: =1-(B5/B2) -> 0.34186433 | D7: Fecha de descarga | E7: 46163

Sheet F3_BRA
A1: Oferta Interna de Energía (ktep) | B1: 321991.35 | D1: Subcriterio | E1: Balance Energético
A2: Consumo Final (ktep) | B2: 288255.58 | D2: Indicador | E2: Índice de excedente energético
D3: Fórmula | E3: 1 - (Consumo Final Total/Oferta Interna Total)
A4: Tasa de excedente energético | B4: =1-(B2/B1) -> 0.10477227 | D4: País | E4: Brasil
D5: Fuente | E5: https://www.epe.gov.br/pt/publicacoes-dados-abertos/publicacoes/BEN-Series-Historicas-Completas
D7: Fecha de descarga | E7: 46163

Sheet F3_PRY
A1: Oferta de Energía (ktep) | B1: 7245.91 | D1: Subcriterio | E1: Balance Energético
A2: Consumo Final de Energía (ktep) | B2: 6388.49 | D2: Indicador | E2: Índice de excedente energético
D3: Fórmula | E3: 1 - (Consumo Final Total/Oferta Interna Total)
A4: Tasa de excedente energético | B4: =1-(B2/B1) -> 0.11833158 | D4: País | E4: Paraguay
D5: Fuente | E5: https://minasyenergia.mopc.gov.py/pdf/balance2024/BEN%202024_Paraguay.pdf
D6: Fecha de descarga | E6: 46163

Sheet F3_URY
A1: Oferta de Energía (ktep) | B1: 7169.7 | D1: Subcriterio | E1: Balance Energético
A2: Consumo Final Energético | B2: 6353.4 | D2: Indicador | E2: Índice de excedente energético
D3: Fórmula | E3: 1 - (Consumo Final Total/Oferta Interna Total)
A4: Tasa de excedente energético | B4: =1-(B2/B1) -> 0.11385414 | D4: País | E4: Uruguay
D5: Fuente | E5: https://visualpeb.miem.gub.uy/visualPEB/ben
D6: Fecha de descarga | E6: 46163

Sheet F4
A1: Escenario | B1: ICTML | D1: Subcriterio | E1: Conectividad Marítima | H1: País | I1: Promedio
A2: Paraguay | B2: =I4 -> 8.7183333 | D2: Indicador | E2: Índice de conectividad del transporte marítimo de línea regular (ICTML) | H2: Argentina | I2: =F4_Paises!B14 -> 101.9975
A3: MERCOSUR | B3: =I6 -> 89.043125 | D3: Descripción | E3: Mide la integración de un país en las redes globales de transporte marítimo de línea. | H3: Brasil | I3: =F4_Paises!C14 -> 148.45083
D4: Política de decisión | E4: Mayor ICTML | H4: Paraguay | I4: =F4_Paises!D14 -> 8.7183333
D5: Regla de agregación MERCOSUR | E5: El indicador del escenario MERCOSUR se estimó mediante el promedio aritmético simple de los valores anuales de Argentina, Brasil, Paraguay y Uruguay. El resultado constituye una aproximación de igual ponderación a la conectividad marítima promedio de los países incluidos y no un índice oficial del MERCOSUR publicado por UNCTAD. | H5: Uruguay | I5: =F4_Paises!E14 -> 97.005833
H6: MERCOSUR | I6: =AVERAGE(I2:I5) -> 89.043125
D9: Fuente | E9: https://unctadstat.unctad.org/datacentre/dataviewer/US.LSCI_M
D10: Fecha de descarga | E10: 46164
D11: Nota metodológica | E11: Se utilizó la serie mensual analítica publicada por UNCTAD. Para obtener un valor representativo de 2024, se calculó el promedio aritmético de los doce registros mensuales de cada país. Los resultados se expresan en puntos de índice y toman como referencia una economía teórica con valores promedio en los seis componentes durante el primer trimestre de 2023 igual a 100.
D12: Unidad de medida | E12: Puntos de índice; economía teórica promedio del primer trimestre de 2023 = 100.
A20: << Volver a la Tabla de contenidos

Sheet F4_Paises
A1: t | B1: Argentina | C1: Brasil | D1: Paraguay | E1: Uruguay | G1: Subcriterio | H1: Conectividad Marítima
A2: 1 | B2: 103.08 | C2: 137.18 | D2: 8.76 | E2: 99.19 | G2: Indicador | H2: Índice de conectividad del transporte marítimo de línea regular, mensual (analítico)
A3: 2 | B3: 103.45 | C3: 137.62 | D3: 8.76 | E3: 99.57 | G3: t | H3: Mes
A4: 3 | B4: 105.96 | C4: 142.33 | D4: 8.71 | E4: 100.85 | G4: Descripción | H4: Esta tabla presenta el Índice de Conectividad del Transporte Marítimo de Línea (ICTML), que mide la integración de un país en las redes globales de transporte marítimo de línea.
A5: 4 | B5: 106.1 | C5: 142.84 | D5: 8.71 | E5: 101.01
A6: 5 | B6: 104.98 | C6: 141.78 | D6: 8.71 | E6: 99.9 | G6: Fuente | H6: https://unctadstat.unctad.org/datacentre/dataviewer/US.LSCI_M
A7: 6 | B7: 101.74 | C7: 144.69 | D7: 8.71 | E7: 95.8 | G7: Fecha de descarga | H7: 46164
A8: 7 | B8: 101.78 | C8: 157.03 | D8: 8.71 | E8: 95.81
A9: 8 | B9: 99.36 | C9: 155.68 | D9: 8.71 | E9: 93.38
A10: 9 | B10: 99.3 | C10: 156.56 | D10: 8.71 | E10: 94.57
A11: 10 | B11: 99.35 | C11: 155.63 | D11: 8.71 | E11: 94.61
A12: 11 | B12: 99.41 | C12: 154.65 | D12: 8.71 | E12: 94.67
A13: 12 | B13: 99.46 | C13: 155.42 | D13: 8.71 | E13: 94.71
A14: Promedio | B14: =AVERAGE(B2:B13) -> 101.9975 | C14: =AVERAGE(C2:C13) -> 148.45083 | D14: =AVERAGE(D2:D13) -> 8.7183333 | E14: =AVERAGE(E2:E13) -> 97.005833
A17: Nota Metodológica: Debido a que el Índice de Conectividad del Transporte Marítimo de Línea Regular se publica con periodicidad mensual, el valor correspondiente al año 2024 fue calculado mediante el promedio aritmético de los doce registros mensuales de cada país. Posteriormente, el indicador del MERCOSUR se obtuvo mediante el promedio de los índices anuales de Argentina, Brasil, Paraguay y Uruguay. Los valores fueron registrados respetando los separadores decimales de la fuente original.

Sheet F5
A1: Escenario | B1: Densidad de red pavimentada | D1: Subcriterio | E1: Red Vial General | H1: País | I1: Rutas pavimentadas (km) | J1: Superficie (km2) | K1: Densidad
A2: Paraguay | B2: =K4 -> 0.031013443 | D2: Indicador | E2: Densidad de red pavimentada por superficie | H2: Argentina | I2: =F5_ARG!B4 -> 85796 | J2: 2780400 | K2: =I2/J2 -> 0.030857431
A3: MERCOSUR | B3: =K6 -> 0.027703642 | D3: Fórmula | E3: Densidad = L/A | H3: Brasil | I3: =F5_BRA!B1 -> 221820 | J3: 8510420 | K3: =I3/J3 -> 0.026064519
D4: Descripción | E4: Cantidad de kilómetros de red vial existentes por cada kilómetro cuadrado de territorio, expresando el grado de cobertura vial de un territorio. | H4: Paraguay | I4: =F5_PRY!B5 -> 12614.78 | J4: 406752 | K4: =I4/J4 -> 0.031013443
H5: Uruguay | I5: =F5_URY!B24 -> 8716.502 | J5: 176220 | K5: =I5/J5 -> 0.04946375
D6: Política de decisión | E6: Mayor densidad de red vial pavimentada | H6: MERCOSUR | I6: =SUM(I2:I5) -> 328947.28 | J6: =SUM(J2:J5) -> 11873792 | K6: =I6/J6 -> 0.027703642
D7: Estimación MERCOSUR | E7: Para calcular la densidad vial pavimentada del MERCOSUR, se sumó la longitud de los caminos pavimentados y la superficie territorial de los países miembros. Posteriormente, se dividió la longitud total de la red pavimentada entre la superficie agrega, obteniendo así el indicador correspondiente al bloque.
D8: Longitud total de caminos o carreteras pavimentadas (L)
D9: Descripción | E9: Extensión total de las carreteras o caminos de un territorio, medida en kilómetros.
D10: Superficie (A)
D11: Descripción | E11: Por superficie se entiende la superficie total de un país, incluidas las zonas cubiertas por masas de agua interiores y algunas vías navegables costeras. Medida en kilómetros cuadrados.
D12: Fuente | E12: https://datos.bancomundial.org/indicador/AG.SRF.TOTL.K2
D13: Fecha de descarga | E13: 46182
D14: Nota metodológica | E14: Debido a la ausencia de una fuente internacional única que concentre los datos requeridos para la longitud de caminos pavimentados, se recurrió a las instituciones oficiales correspondientes de cada país. Los cálculos individuales y las fuentes utilizadas se presentan en las siguientes hojas.
A19: << Volver a la Tabla de contenidos

Sheet F5_ARG
A1: Red vial nacional pavimentada (km) | B1: 37269 | D1: Subcriterio | E1: Red vial
A2: Red vial provincial pavimentada (km) | B2: 48527 | D2: Rutas pavimentadas (km)
D3: País | E3: Argentina
A4: Red pavimentada (km) | B4: =B1+B2 -> 85796 | D4: Descripción | E4: Longitud de red vial pavimentada
D5: Fuente | E5: https://biblioteca.camarco.org.ar/wp-content/uploads/06-RED-VIAL.pdf
D6: Fecha de descarga | E6: 46182

Sheet F5_BRA
A1: Rutas pavimentadas | B1: 221820 | D1: Subcriterio | E1: Red vial
D2: Rutas pavimentadas (km)
D3: País | E3: Brasil
D4: Descripción | E4: Longitud de red vial pavimentada
D5: Fuente | E5: https://sinaceg.org/analise-sinaceg-brasil-tem-poucas-estradas-pavimentadas/
D6: Fecha de descarga | E6: 46182

Sheet F5_PRY
A1: Año | B1: Total Pavimentada (km) | D1: Subcriterio | E1: Red vial
A2: 2023 | B2: =10289.09+2063.24 -> 12352.33 | D2: Rutas pavimentadas (km)
A3: 2025 | B3: =10670.39+2206.84 -> 12877.23 | D3: País | E3: Paraguay
D4: Descripción | E4: Longitud de red vial pavimentada
A5: Estimación 2024 | B5: =AVERAGE(B2:B3) -> 12614.78 | D5: Fuente | E5: https://mopc.gov.py/red-vial/
D6: Fecha de descarga | E6: 46182
A9: * El valor correspondiente a 2024 se estimó mediante interpolación lineal, utilizando el promedio de los valores observados en 2023 y 2025.

Sheet F5_URY
A1: Departamento | B1: Total | C1: Hormigón | D1: Concreto asfáltico | E1: Tratamiento bituminoso | F1: Tosca | H1: Subcriterio | I1: Red vial
A2: Total País | B2: 8940.402 | C2: 516.155 | D2: 5110.84 | E2: 3089.507 | F2: 223.9 | H2: Rutas pavimentadas (km)
A3: Artigas | B3: 394.05 | C3: 1.45 | D3: 173.4 | E3: 197 | F3: 22.2 | H3: País | I3: Uruguay
A4: Canelones | B4: 1139.44 | C4: 40.14 | D4: 931.45 | E4: 167.85 | F4: - | H4: Descripción | I4: Longitud de la red vial del Uruguay, por tipo de pavimento y departamento (kilómetros)
A5: Cerro Largo | B5: 488.35 | C5: 6.7 | D5: 111.9 | E5: 369.75 | F5: - | H5: Fuente | I5: https://www.gub.uy/instituto-nacional-estadistica/comunicacion/publicaciones/anuario-estadistico-nacional-2025-vol-102/47-transporte-comunicaciones-0
A6: Colonia | B6: 571.3 | C6: 50.6 | D6: 412.8 | E6: 107.9 | F6: -
A7: Durazno | B7: 434.15 | C7: 7.88 | D7: 183 | E7: 165.57 | F7: 77.7 | H7: Fecha de descarga | I7: 46177
A8: Flores | B8: 287.05 | C8: 52.95 | D8: 183.3 | E8: 50.8 | F8: -
A9: Florida | B9: 608.23 | C9: - | D9: 228.73 | E9: 379.5 | F9: -
A10: Lavalleja | B10: 286.9 | C10: - | D10: 187.1 | E10: 99.8 | F10: -
A11: Maldonado | B11: 371.61 | C11: - | D11: 245.76 | E11: 125.85 | F11: -
A12: Montevideo | B12: 152.52 | C12: 103.52 | D12: 49 | E12: - | F12: -
A13: Paysandú | B13: 430.9 | C13: 10.8 | D13: 355 | E13: 65.1 | F13: -
A14: Río Negro | B14: 453.9 | C14: 109.5 | D14: 284.6 | E14: 59.8 | F14: -
A15: Rivera | B15: 430.5 | C15: - | D15: 166.4 | E15: 245.7 | F15: 18.4
A16: Rocha | B16: 646.5 | C16: - | D16: 331.5 | E16: 222.9 | F16: 92.1
A17: Salto | B17: 328.4 | C17: - | D17: 118 | E17: 210.4 | F17: -
A18: San José | B18: 464.557 | C18: 91.65 | D18: 316.25 | E18: 56.657 | F18: -
A19: Soriano | B19: 527.215 | C19: 38.465 | D19: 327.3 | E19: 161.45 | F19: -
A20: Tacuarembó | B20: 654.48 | C20: - | D20: 287 | E20: 353.98 | F20: 13.5
A21: Treinta y Tres | B21: 270.35 | C21: 2.5 | D21: 218.35 | E21: 49.5 | F21: -
A23: * Se considera como ruta pavimentada la suma de hormigón, concreto asfáltico y tratamiento bituminoso, excluyendo los tramos de tosca
A24: Ruta pavimentada | B24: =C2+D2+E2 -> 8716.502

Sheet F6
A1: Escenario | B1: Carga aérea | D1: Subcriterio | E1: Logística Aérea | G1: País | H1: Carga aérea
A2: Paraguay | B2: =H4 -> 29441.229 | D2: Indicador | E2: Carga aérea | G2: Argentina | H2: =F6_ARG!E14 -> 189449
A3: MERCOSUR | B3: =H6 -> 1623994.7 | D3: Descripción | E3: Cantidad total de mercancías transportadas por vía aérea, medida en toneladas. Incluye exportaciones, importaciones y otras cargas comerciales movilizadas a través de los aeropuertos. | G3: Brasil | H3: =F6_BRA!C7 -> 1380062.4
G4: Paraguay | H4: =F6_PRY!C18 -> 29441.229
G5: Uruguay | H5: =F6_URY!B3 -> 25042.07
D6: Política de decisión | E6: Mayor volumen de carga aérea | G6: MERCOSUR | H6: =SUM(H2:H5) -> 1623994.7
D7: Estimación MERCOSUR | E7: Se sumó el volumen de carga aérea transportada correspondiente a Argentina, Brasil, Paraguay y Uruguay.
D8: Nota metodológica | E8: Debido a la ausencia de una fuente internacional única que concentre los datos requeridos, se recurrió a las instituciones oficiales correspondientes de cada país. Los cálculos individuales y las fuentes utilizadas se presentan en las siguientes hojas.
A21: << Volver a la Tabla de contenidos

Sheet F6_ARG
A1: t | B1: Cabotaje | C1: Exportación | D1: Importación | E1: TOTAL | G1: Subcriterio | H1: Conectividad aérea
A2: 1 | B2: 238 | C2: 8588 | D2: 5731 | E2: =SUM(B2:D2) -> 14557 | G2: Indicador | H2: Carga aérea
A3: 2 | B3: 290 | C3: 6920 | D3: 5461 | E3: =SUM(B3:D3) -> 12671 | G3: País | H3: Argentina
A4: 3 | B4: 337 | C4: 7912 | D4: 6755 | E4: =SUM(B4:D4) -> 15004 | G4: t | H4: Mes
A5: 4 | B5: 275 | C5: 8782 | D5: 6449 | E5: =SUM(B5:D5) -> 15506 | G5: Descripción | H5: Carga transportada (en toneladas)
A6: 5 | B6: 513 | C6: 7761 | D6: 7540 | E6: =SUM(B6:D6) -> 15814 | G6: Fuente | H6: https://consultas-publicas.anac.gob.ar/estadisticas-dnta/
A7: 6 | B7: 429 | C7: 6963 | D7: 7187 | E7: =SUM(B7:D7) -> 14579 | G7: Fecha de descarga | H7: 46174
A8: 7 | B8: 461 | C8: 6602 | D8: 7159 | E8: =SUM(B8:D8) -> 14222
A9: 8 | B9: 484 | C9: 7272 | D9: 7095 | E9: =SUM(B9:D9) -> 14851
A10: 9 | B10: 466 | C10: 8852 | D10: 7199 | E10: =SUM(B10:D10) -> 16517
A11: 10 | B11: 442 | C11: 9723 | D11: 7830 | E11: =SUM(B11:D11) -> 17995
A12: 11 | B12: 508 | C12: 9444 | D12: 8831 | E12: =SUM(B12:D12) -> 18783
A13: 12 | B13: 618 | C13: 11225 | D13: 7107 | E13: =SUM(B13:D13) -> 18950
A14: TOTAL 2024 | E14: =SUM(E2:E13) -> 189449

Sheet F6_BRA
A1: Año | B1: Naturaleza | C1: Despegues | E1: Subcriterio | F1: Conectividad aérea
A2: 2024 | B2: Doméstica | C2: 488.05798 | E2: Indicador | F2: Carga aérea
A3: 2024 | B3: Internacional | C3: 892.00438 | E3: País | F3: Brasil
A4: TOTAL 2024 | C4: =SUM(C2:C3) -> 1380.0624 | E4: Descripción | F4: Evolución anual del transporte de carga y correo pagado: mercados nacionales e internacionales (en miles de toneladas).
E5: Fuente | F5: https://www.gov.br/anac/pt-br/assuntos/dados-e-estatisticas/mercado-do-transporte-aereo/panorama-do-mercado/anuario-transporte-aereo
E6: Fecha de descarga | F6: 46174
A7: Total en toneladas | C7: =C4*1000 -> 1380062.4

Sheet F6_PRY
A1: t | B1: Aeropuerto Silvio Pettirossi | C1: Aeropuerto Internacional Guaraní | E1: Subcriterio | F1: Conectividad aérea
A2: 1 | B2: 1192076 | C2: 738540 | E2: Indicador | F2: Carga aérea
A3: 2 | B3: 1267937 | C3: 716508 | E3: País | F3: Paraguay
A4: 3 | B4: 1267561 | C4: 983095 | E4: t | F4: Mes
A5: 4 | B5: 1700819 | C5: 814847 | E5: Descripción | F5: Cargas aéreas de importación y exportación de vuelos cargueros y vuelos regulares mixtos (en kg).
A6: 5 | B6: 1514390 | C6: 876244 | E6: Fuente | F6: https://www.dinac.gov.py/v3/index.php/dinac/subdirecciones/sub-direccion-de-transporte-aereo/item/122-datos-estad%C3%ADsticos-de-movimiento
A7: 6 | B7: 1343547 | C7: 1085761 | E7: Fecha de descarga | F7: 46167
A8: 7 | B8: 1599982 | C8: 906574
A9: 8 | B9: 1528219 | C9: 973510
A10: 9 | B10: 1406353 | C10: 909793
A11: 10 | B11: 1752275 | C11: 907179
A12: 11 | B12: 1710804 | C12: 1208354
A13: 12 | B13: 1745054 | C13: 1291807
B14: =SUM(B2:B13) -> 18029017 | C14: =SUM(C2:C13) -> 11412212
A16: TOTAL (kg) | C16: =B14+C14 -> 29441229
A18: Total en toneladas | C18: =C16/1000 -> 29441.229

Sheet F6_URY
A1: Entrada | B1: 14374.52 | D1: Subcriterio | E1: Conectividad aérea
A2: Salida | B2: 10667.55 | D2: Indicador | E2: Carga aérea
A3: Total | B3: =B1+B2 -> 25042.07 | D3: País | E3: Uruguay
D4: Descripción | E4: Movimiento de cargas por el Aeropuerto Internacional de Carrasco (en toneladas)
D5: Fuente | E5: https://www.dinacia.gub.uy/documento/boletin-estadistico-ano-2024
D6: Fecha de descarga | E6: 46167

Sheet F7
A1: Escenario | B1: IGI | D1: Subcriterio | E1: Innovación y Desarrollo Tecnológico | H1: País | I1: Puntuación
A2: Paraguay | B2: 21.9 | D2: Indicador | E2: Índice Global de Innovación (IGI) | H2: Argentina | I2: 26.4
A3: MERCOSUR | B3: 27.525 | D3: Descripción | E3: El Índice Global de Innovación, publicado anualmente por la OMPI, evalúa y clasifica la capacidad innovadora de los países a través de dos bloques fundamentales: los Insumos de Innovación, que miden los factores habilitadores de una economía (instituciones, capital humano, infraestructura y sofisticación de mercados y negocios), y los Resultados de la Innovación, que analizan los productos reales obtenidos mediante la producción de conocimientos, tecnología y bienes creativos. | H3: Brasil | I3: 32.7
H4: Paraguay | I4: 21.9
H5: Uruguay | I5: 29.1
H6: MERCOSUR | I6: =AVERAGE(I2:I5) -> 27.525
D9: Política de decisión | E9: Mayor Índice Global de Innovación
D10: Estimación MERCOSUR | E10: Se calculó el promedio de las puntuaciones correspondientes a Argentina, Brasil, Paraguay y Uruguay.
D11: Fuente | E11: https://www.wipo.int/web-publications/global-innovation-index-2024/en/index.html
D12: Fecha de descarga | E12: 46164
A23: << Volver a la Tabla de contenidos

Sheet F8
A1: Escenario | B1: Fitness | D1: Subcriterio | E1: Economic Fitness | G1: País | H1: Fitness
A2: Paraguay | B2: =H4 -> 0.67985949 | D2: Indicador | E2: Fitness de países | G2: Argentina | H2: 0.80848796
A3: MERCOSUR | B3: 1.4812096 | D3: Descripción | E3: Es una métrica no monetaria diseñada para medir la competitividad y poder productivo de los países. | G3: Brasil | H3: 1.5609597
G4: Paraguay | H4: 0.67985949
D5: Política de decisión | E5: Mayor Fitness | G5: Uruguay | H5: 0.77769871
D6: Fuente | E6: https://doi.org/10.7910/DVN/T4CHWJ | G6: MERCOSUR | H6: 1.4812096
D7: Fecha de descarga | E7: 46162
D8: Estimación MERCOSUR | E8: Para obtener el Fitness del MERCOSUR como bloque, se sumaron las exportaciones de sus países miembros, reemplazando así los registros individuales por un único registro agregado. Sobre esta base se aplicó posteriormente la metodología de Economic Fitness.
D9: Nota metodológica | E9: El Fitness de los países se calculó mediante un código desarrollado en Python, adaptado a partir del código original implementado en MATLAB por S. González (2021), siguiendo la metodología de Tacchella et al. (2012). Se utilizó la base de datos de comercio internacional HS92 de 4 dígitos de Growth Lab de Harvard University.
A23: << Volver a la Tabla de contenidos

Sheet F9
A1: Escenario | B1: Capacidades Productivas Acumuladas | D1: Subcriterio | E1: Capacidades Productivas | H1: País | I1: Capacidades Productivas Acumuladas
A2: Paraguay | B2: =I4 -> 733.74306 | D2: Indicador | E2: Capacidades Productivas Acumuladas | H2: Argentina | I2: =F9_Paises!B19 -> 646.08393
A3: MERCOSUR | B3: =F9_MERCOSUR!B14 -> 821.5208 | D3: Fórmula | E3: Σ(VCR de productos * Complejidad de productos (Qp)) | H3: Brasil | I3: =F9_Paises!B20 -> 768.12528
D4: Política de decisión | E4: Mayor Capacidad Productiva Acumulada | H4: Paraguay | I4: =F9_Paises!B21 -> 733.74306
D5: Fuente | E5: https://doi.org/10.7910/DVN/T4CHWJ | H5: Uruguay | I5: =F9_Paises!B22 -> 1026.9763
D6: Fecha de descarga | E6: 46162
A24: << Volver a la Tabla de contenidos

Sheet F9_Paises
